<?xml version="1.0" encoding="utf-8"?>

<robot name="basic_link">

     <!-- Primer Eslabón -->
    <link name="base_link">
        <visual>
            <origin xyz="0.0 0.0 0.05" rpy="0.0 0.0 0.0"/>
            <geometry>
                <box size="0.05 0.05 0.10"/>
            </geometry>
            <material name="verde">
                <color rgba="0.0 1.0 0.0 1.0"/>
            </material>
        </visual>
        <collision>
            <origin xyz="0.0 0.0 0.05" rpy="0.0 0.0 0.0"/>
            <geometry>
                <box size="0.05 0.05 0.10"/>
            </geometry>
        </collision>
        <inertial>
            <mass value="1.0"/>
            <origin xyz="0.0 0.0 0.0" rpy="0.0 0.0 0.0"/>
            <inertia ixx="1.0" ixy="0.0" ixz="0.0" iyy="1.0" iyz="0.0" izz="1.0"/> 
        </inertial>
    </link>

     <!-- Segundo Eslabón -->
    <link name="link_1">
        <visual>
            <origin xyz="0.0 0.0 0.075" rpy="0.0 0.0 0.0"/>
            <geometry>
                <box size="0.05 0.05 0.10"/>
            </geometry>
            <material name="blanco">
                <color rgba="1.0 1.0 1.0 1.0"/>
            </material>
        </visual>
        <collision>
            <origin xyz="0.0 0.0 0.075" rpy="0.0 0.0 0.0"/>
            <geometry>
                <box size="0.05 0.05 0.10"/>
            </geometry>
        </collision>
        <inertial>
            <mass value="1.0"/>
            <origin xyz="0.0 0.0 0.0" rpy="0.0 0.0 0.0"/>
            <inertia ixx="1.0" ixy="0.0" ixz="0.0" iyy="1.0" iyz="0.0" izz="1.0"/> 
        </inertial>
    </link>

     <!-- Tercer Eslabón -->
    <link name="link_2">
        <visual>
            <origin xyz="0.0 0.0 0.075" rpy="0.0 0.0 0.0"/>
            <geometry>
                <box size="0.05 0.05 0.10"/>
            </geometry>
            <material name="rojo">
                <color rgba="1.0 0.0 0.0 1.0"/>
            </material>
        </visual>
        <collision>
            <origin xyz="0.0 0.0 0.075" rpy="0.0 0.0 0.0"/>
            <geometry>
                <box size="0.05 0.05 0.10"/>
            </geometry>
        </collision>
        <inertial>
            <mass value="1.0"/>
            <origin xyz="0.0 0.0 0.0" rpy="0.0 0.0 0.0"/>
            <inertia ixx="1.0" ixy="0.0" ixz="0.0" iyy="1.0" iyz="0.0" izz="1.0"/> 
        </inertial>
    </link>

     <!-- Primera Junta Rotacional -->
    <joint name="base_link_to_link_1_joint" type="revolute" >
        <parent link="base_link" />
        <child link="link_1" />
        <axis xyz="1 0 0" />
        <limit lower="-1.57" upper="1.57" velocity="50" effort="10" />
        <origin xyz="0.0 0.0 0.125" rpy="0.0 0.0 0.0" />   
    </joint>

     <!-- Segunda Junta Rotacional -->
    <joint name="link_1_to_link_2_joint" type="revolute" >
        <parent link="link_1" />
        <child link="link_2" />
        <axis xyz="0 1 0" />
        <limit lower="-1.57" upper="1.57" velocity="50" effort="10" />
        <origin xyz="0.0 0.0 0.15" rpy="0.0 0.0 0.0" />   
    </joint>

</robot>
